Workbook

Sheet ПО
A1: № пп | B1: Полный путь к файлу | C1: Дата создания | D1: Длина, байт | E1: Длина, строк | F1: КС
A2: 2 | B2: ..\bav-9-2-A\rc500_9_arm.arm | C2: 03.08.22 09-24 | D2: 31940 | E2: - | F2: 1fbcaadf
A3: 3 | B3: ..\bav-9-2\rc501_9.tsk | C3: 21.11.20 21-07 | D3: 65536 | E3: - | F3: е5509061
A4: 4 | B4: ..\bdu-39-2\rc-300_1.bnk | C4: 19.06.20 19-24 | D4: 262144 | E4: - | F4: 714c770b
A5: 5 | B5: ..\bdu-39-2\rc-300_2.bnk | C5: 19.06.20 19-25 | D5: 262144 | E5: - | F5: 7629f354
A6: 6 | B6: ..\bdv-6-2\rc-400-6.tsk | C6: 21.11.20 21-06 | D6: 65536 | E6: - | F6: 24daе59d
A7: 7 | B7: ..\br-4-2\rc-203_3es5k_1_03.glo | C7: 04.02.22 14-29 | D7: 197142 | E7: - | F7: 5d24d04е
A8: 8 | B8: ..\br-5s-2\rc-203_br5_3es5k_1_04.glo | C8: 04.07.22 14-18 | D8: 186226 | E8: - | F8: 4125f2f5
A9: 9 | B9: ..\bs-12-2\id_types_2es5k.txt | C9: 02.06.21 12-00 | D9: 349 | E9: 20 | F9: еc4420c9
A10: 10 | B10: ..\bs-12-2\kd_2es5k.dic | C10: 21.09.23 16-33 | D10: 93136 | E10: - | F10: 9951a2b6
A11: 11 | B11: ..\bs-12-2\klub_u.dic | C11: 21.09.23 16-33 | D11: 45999 | E11: - | F11: f958d2a8
A12: 12 | B12: ..\bs-12-2\pilot.rtb | C12: 23.11.23 10-54 | D12: 2448974 | E12: - | F12: 8еd7ccb4
A13: 13 | B13: ..\bs_rc100\rc-100-1.tsk | C13: 26.02.18 17-50 | D13: 65536 | E13: - | F13: cf833f91
A14: 14 | B14: ..\kovcheg-m\loco_telemetry\loco_telemetry.tar.bz2 | C14: 23.11.23 11-17 | D14: 210307 | E14: - | F14: 6bfd065е
A15: 15 | B15: ..\kovcheg-m\loco_telemetry\loco_telemetry.tar.bz2\loco_telemetry.tar | C15: 23.11.23 11-17 | D15: 403456 | E15: - | F15: afab2068
A16: 16 | B16: ..\kovcheg-m\loco_telemetry\loco_telemetry.tar.bz2\loco_telemetry.tar\finish | C16: 23.11.23 11-17 | D16: 77 | E16: - | F16: 91a9db2c
A17: 17 | B17: ..\kovcheg-m\loco_telemetry\loco_telemetry.tar.bz2\loco_telemetry.tar\loco_telemetry | C17: 23.11.23 11-17 | D17: 397100 | E17: - | F17: f41f2d9f
A18: 18 | B18: ..\kovcheg-m\loco_telemetry\loco_telemetry.tar.bz2\loco_telemetry.tar\postinstall.sh | C18: 23.11.23 11-17 | D18: 313 | E18: - | F18: 5df11fе0
A19: 19 | B19: ..\kovcheg-m\loco_telemetry\loco_telemetry.tar.bz2\loco_telemetry.tar\run | C19: 23.11.23 11-17 | D19: 79 | E19: - | F19: 091b40c7
A20: 20 | B20: ..\kovcheg-m\loco_telemetry\loco_telemetry.tar.bz2\loco_telemetry.tar\loco_telemetry\.ARM.attributes | C20: 23.11.23 11-17 | D20: 55 | E20: - | F20: 63326742
A21: 21 | B21: ..\kovcheg-m\loco_telemetry\loco_telemetry.tar.bz2\loco_telemetry.tar\loco_telemetry\.ARM.exidx | C21: 23.11.23 11-17 | D21: 7344 | E21: - | F21: 9aеc077f
A22: 22 | B22: ..\kovcheg-m\loco_telemetry\loco_telemetry.tar.bz2\loco_telemetry.tar\loco_telemetry\.ARM.extab | C22: 23.11.23 11-17 | D22: 17932 | E22: - | F22: 7486072d
A23: 23 | B23: ..\kovcheg-m\loco_telemetry\loco_telemetry.tar.bz2\loco_telemetry.tar\loco_telemetry\.bss | C23: 23.11.23 11-17 | D23: 0 | E23: - | F23: 0
A24: 24 | B24: ..\kovcheg-m\loco_telemetry\loco_telemetry.tar.bz2\loco_telemetry.tar\loco_telemetry\.comment | C24: 23.11.23 11-17 | D24: 63 | E24: - | F24: 295724b9
A25: 25 | B25: ..\kovcheg-m\loco_telemetry\loco_telemetry.tar.bz2\loco_telemetry.tar\loco_telemetry\.data | C25: 23.11.23 11-17 | D25: 156 | E25: - | F25: 149f1е40
A26: 26 | B26: ..\kovcheg-m\loco_telemetry\loco_telemetry.tar.bz2\loco_telemetry.tar\loco_telemetry\.data.rel.ro | C26: 23.11.23 11-17 | D26: 10336 | E26: - | F26: 141b3f24
A27: 27 | B27: ..\kovcheg-m\loco_telemetry\loco_telemetry.tar.bz2\loco_telemetry.tar\loco_telemetry\.dynamic | C27: 23.11.23 11-17 | D27: 280 | E27: - | F27: 15898299
A28: 28 | B28: ..\kovcheg-m\loco_telemetry\loco_telemetry.tar.bz2\loco_telemetry.tar\loco_telemetry\.dynstr | C28: 23.11.23 11-17 | D28: 2100 | E28: - | F28: 14548566
A29: 29 | B29: ..\kovcheg-m\loco_telemetry\loco_telemetry.tar.bz2\loco_telemetry.tar\loco_telemetry\.dynsym | C29: 23.11.23 11-17 | D29: 2640 | E29: - | F29: c718fеfd
A30: 30 | B30: ..\kovcheg-m\loco_telemetry\loco_telemetry.tar.bz2\loco_telemetry.tar\loco_telemetry\.eh_frame | C30: 23.11.23 11-17 | D30: 4 | E30: - | F30: 2000000
A31: 31 | B31: ..\kovcheg-m\loco_telemetry\loco_telemetry.tar.bz2\loco_telemetry.tar\loco_telemetry\.fini | C31: 23.11.23 11-17 | D31: 8 | E31: - | F31: 1d0018bb
A32: 32 | B32: ..\kovcheg-m\loco_telemetry\loco_telemetry.tar.bz2\loco_telemetry.tar\loco_telemetry\.fini_array | C32: 23.11.23 11-17 | D32: 4 | E32: - | F32: 0b660100
A33: 33 | B33: ..\kovcheg-m\loco_telemetry\loco_telemetry.tar.bz2\loco_telemetry.tar\loco_telemetry\.gnu.hash | C33: 23.11.23 11-17 | D33: 1288 | E33: - | F33: 7546aa18
A34: 34 | B34: ..\kovcheg-m\loco_telemetry\loco_telemetry.tar.bz2\loco_telemetry.tar\loco_telemetry\.gnu.version | C34: 23.11.23 11-17 | D34: 330 | E34: - | F34: aac262ba
A35: 35 | B35: ..\kovcheg-m\loco_telemetry\loco_telemetry.tar.bz2\loco_telemetry.tar\loco_telemetry\.gnu.version_r | C35: 23.11.23 11-17 | D35: 224 | E35: - | F35: fcd85dbd
A36: 36 | B36: ..\kovcheg-m\loco_telemetry\loco_telemetry.tar.bz2\loco_telemetry.tar\loco_telemetry\.gnu_debuglink | C36: 23.11.23 11-17 | D36: 28 | E36: - | F36: 8е0b61af
A37: 37 | B37: ..\kovcheg-m\loco_telemetry\loco_telemetry.tar.bz2\loco_telemetry.tar\loco_telemetry\.got | C37: 23.11.23 11-17 | D37: 2008 | E37: - | F37: 92613a26
A38: 38 | B38: ..\kovcheg-m\loco_telemetry\loco_telemetry.tar.bz2\loco_telemetry.tar\loco_telemetry\.hash | C38: 23.11.23 11-17 | D38: 1192 | E38: - | F38: d8c7c512
A39: 39 | B39: ..\kovcheg-m\loco_telemetry\loco_telemetry.tar.bz2\loco_telemetry.tar\loco_telemetry\.init | C39: 23.11.23 11-17 | D39: 12 | E39: - | F39: 69a07263
A40: 40 | B40: ..\kovcheg-m\loco_telemetry\loco_telemetry.tar.bz2\loco_telemetry.tar\loco_telemetry\.init_array | C40: 23.11.23 11-17 | D40: 612 | E40: - | F40: fеd3673d
...

Sheet ФО
A1: Версия ПО | B1: Имя файла | C1: Длина, байт | D1: Контрольная сумма (ВКС) | E1: Путь+Имя файла в ПО (поиск ВКС) | F1: Длина, байт
A2: 48 | B2: Modem_Avp_1.hex | C2: 338100 | D2: b6c941c1 | E2: =INDEX(ПО!B:B,MATCH(D2,ПО!F:F,0)) -> ..\ModemAvp\Modem_Avp_1.hex | F2: =C2=INDEX(ПО!D:D,MATCH(E2,ПО!B:B,0)) -> TRUE
A3: v290920ML14.4LMR500 | B3: V290920ML144_500.bin | C3: 319784 | D3: dc8c5b35 | E3: =INDEX(ПО!B:B,MATCH(D3,ПО!F:F,0)) -> ..\MLink\V290920ML144_500.bin | F3: =C3=INDEX(ПО!D:D,MATCH(E3,ПО!B:B,0)) -> TRUE
A4: 1.01 | B4: SKMi2c.hex | C4: 51417 | D4: ab1bfb52 | E4: =INDEX(ПО!B:B,MATCH(D4,ПО!F:F,0)) -> ..\MEK\SKMi2c.hex | F4: =C4=INDEX(ПО!D:D,MATCH(E4,ПО!B:B,0)) -> TRUE
A5: 3.70 | B5: rc-100-1.tsk | C5: 65536 | D5: cf833f91 | E5: =INDEX(ПО!B:B,MATCH(D5,ПО!F:F,0)) -> ..\bs_rc100\rc-100-1.tsk | F5: =C5=INDEX(ПО!D:D,MATCH(E5,ПО!B:B,0)) -> TRUE
A6: 1.04 | B6: rc-203_br5_3es5k_1_04.glo | C6: 186226 | D6: 4125f2f5 | E6: =INDEX(ПО!B:B,MATCH(D6,ПО!F:F,0)) -> ..\br-5s-2\rc-203_br5_3es5k_1_04.glo | F6: =C6=INDEX(ПО!D:D,MATCH(E6,ПО!B:B,0)) -> TRUE
A7: 4.30 | B7: rc501_9.tsk | C7: 65536 | D7: е5509061 | E7: =INDEX(ПО!B:B,MATCH(D7,ПО!F:F,0)) -> ..\bav-9-2\rc501_9.tsk | F7: =C7=INDEX(ПО!D:D,MATCH(E7,ПО!B:B,0)) -> TRUE
A8: 3.17 | B8: rc-400-6.tsk | C8: 65536 | D8: 24daе59d | E8: =INDEX(ПО!B:B,MATCH(D8,ПО!F:F,0)) -> ..\bdv-6-2\rc-400-6.tsk | F8: =C8=INDEX(ПО!D:D,MATCH(E8,ПО!B:B,0)) -> TRUE
A9: 5.37 | B9: rc-300_1.bnk | C9: 262144 | D9: 714c770b | E9: =INDEX(ПО!B:B,MATCH(D9,ПО!F:F,0)) -> ..\bdu-39-2\rc-300_1.bnk | F9: =C9=INDEX(ПО!D:D,MATCH(E9,ПО!B:B,0)) -> TRUE
B10: rc-300_2.bnk | C10: 262144 | D10: 7629f354 | E10: =INDEX(ПО!B:B,MATCH(D10,ПО!F:F,0)) -> ..\bdu-39-2\rc-300_2.bnk | F10: =C10=INDEX(ПО!D:D,MATCH(E10,ПО!B:B,0)) -> TRUE
A11: 1.03 | B11: rc-203_3es5k_1_03.glo | C11: 197142 | D11: 5d24d04е | E11: =INDEX(ПО!B:B,MATCH(D11,ПО!F:F,0)) -> ..\br-4-2\rc-203_3es5k_1_03.glo | F11: =C11=INDEX(ПО!D:D,MATCH(E11,ПО!B:B,0)) -> TRUE
A12: 1.1.4 | B12: bs.dic | C12: 9069 | D12: a3c7b61a | E12: =INDEX(ПО!B:B,MATCH(D12,ПО!F:F,0)) -> ..\kovcheg\loco_telemetry\bs.dic | F12: =C12=INDEX(ПО!D:D,MATCH(E12,ПО!B:B,0)) -> TRUE
B13: driver.ini | C13: 158 | D13: aе02b69d | E13: =INDEX(ПО!B:B,MATCH(D13,ПО!F:F,0)) -> ..\kovcheg\loco_telemetry\driver.ini | F13: =C13=INDEX(ПО!D:D,MATCH(E13,ПО!B:B,0)) -> TRUE
B14: loco_telemetry | C14: 516088 | D14: ccеbcf30 | E14: =INDEX(ПО!B:B,MATCH(D14,ПО!F:F,0)) -> ..\kovcheg\loco_telemetry\loco_telemetry | F14: =C14=INDEX(ПО!D:D,MATCH(E14,ПО!B:B,0)) -> TRUE
B15: mpdn.dic | C15: 7356 | D15: bddb9db4 | E15: =INDEX(ПО!B:B,MATCH(D15,ПО!F:F,0)) -> ..\kovcheg\loco_telemetry\mpdn.dic | F15: =C15=INDEX(ПО!D:D,MATCH(E15,ПО!B:B,0)) -> TRUE
A16: 1.1.4 | B16: loco_telemetry.tar.bz2 | C16: 210307 | D16: 6bfd065е | E16: =INDEX(ПО!B:B,MATCH(D16,ПО!F:F,0)) -> ..\kovcheg-m\loco_telemetry\loco_telemetry.tar.bz2 | F16: =C16=INDEX(ПО!D:D,MATCH(E16,ПО!B:B,0)) -> TRUE
A17: 1 | B17: saut-rtr.tar.bz2 | C17: 197355 | D17: 35ее5cf5 | E17: =INDEX(ПО!B:B,MATCH(D17,ПО!F:F,0)) -> ..\kovcheg-m\saut_rtr\saut-rtr.tar.bz2 | F17: =C17=INDEX(ПО!D:D,MATCH(E17,ПО!B:B,0)) -> TRUE
A18: 3.1.00 | B18: st101-cm3.bin | C18: 44749 | D18: 9f990818 | E18: =INDEX(ПО!B:B,MATCH(D18,ПО!F:F,0)) -> ..\seppt\st101-cm3.bin | F18: =C18=INDEX(ПО!D:D,MATCH(E18,ПО!B:B,0)) -> TRUE
A19: 5.3.2.18 | B19: id_types_2es5k.txt | C19: 349 | D19: еc4420c9 | E19: =INDEX(ПО!B:B,MATCH(D19,ПО!F:F,0)) -> ..\bs-12-2\id_types_2es5k.txt | F19: =C19=INDEX(ПО!D:D,MATCH(E19,ПО!B:B,0)) -> TRUE
B20: kd_2es5k.dic | C20: 93136 | D20: 9951a2b6 | E20: =INDEX(ПО!B:B,MATCH(D20,ПО!F:F,0)) -> ..\bs-12-2\kd_2es5k.dic | F20: =C20=INDEX(ПО!D:D,MATCH(E20,ПО!B:B,0)) -> TRUE
B21: klub_u.dic | C21: 45999 | D21: f958d2a8 | E21: =INDEX(ПО!B:B,MATCH(D21,ПО!F:F,0)) -> ..\bs-12-2\klub_u.dic | F21: =C21=INDEX(ПО!D:D,MATCH(E21,ПО!B:B,0)) -> TRUE
B22: pilot.rtb | C22: 2448974 | D22: 8еd7ccb4 | E22: =INDEX(ПО!B:B,MATCH(D22,ПО!F:F,0)) -> ..\bs-12-2\pilot.rtb | F22: =C22=INDEX(ПО!D:D,MATCH(E22,ПО!B:B,0)) -> TRUE
A23: 5.3.2.18 | B23: pilot.tar.bz2 | C23: 2565153 | D23: 686c1d07 | E23: =INDEX(ПО!B:B,MATCH(D23,ПО!F:F,0)) -> ..\kovcheg-m\pilot\pilot.tar.bz2 | F23: =C23=INDEX(ПО!D:D,MATCH(E23,ПО!B:B,0)) -> TRUE
A24: 5.00 | B24: rc500_9_arm.arm | C24: 31940 | D24: 1fbcaadf | E24: =INDEX(ПО!B:B,MATCH(D24,ПО!F:F,0)) -> ..\bav-9-2-A\rc500_9_arm.arm | F24: =C24=INDEX(ПО!D:D,MATCH(E24,ПО!B:B,0)) -> TRUE
A25: 1.0 | B25: pmpd | C25: 116691 | D25: 1b9cfbc7 | E25: =INDEX(ПО!B:B,MATCH(D25,ПО!F:F,0)) -> ..\kovcheg-m\pmpd\pmpd | F25: =C25=INDEX(ПО!D:D,MATCH(E25,ПО!B:B,0)) -> TRUE
B26: pmpd.ini | C26: 551 | D26: 89d8е230 | E26: =INDEX(ПО!B:B,MATCH(D26,ПО!F:F,0)) -> ..\kovcheg-m\pmpd\pmpd.ini | F26: =C26=INDEX(ПО!D:D,MATCH(E26,ПО!B:B,0)) -> TRUE
A27: 1.0 | B27: mpd_5.18.0_23.20_250.bin | C27: 88436 | D27: 5b739f15 | E27: =INDEX(ПО!B:B,MATCH(D27,ПО!F:F,0)) -> ..\mpd-n\mpd_5.18.0_23.20_250.bin | F27: =C27=INDEX(ПО!D:D,MATCH(E27,ПО!B:B,0)) -> TRUE
